{
 "cells": [
  {
   "cell_type": "markdown",
   "metadata": {},
   "source": [
    "# Python Insights - Analisando Dados com Python\n",
    "\n",
    "### Case - Cancelamento de Clientes\n",
    "\n",
    "Você foi contratado por uma empresa com mais de 800 mil clientes para um projeto de Dados. Recentemente a empresa percebeu que da sua base total de clientes, a maioria são clientes inativos, ou seja, que já cancelaram o serviço.\n",
    "\n",
    "Precisando melhorar seus resultados ela quer conseguir entender os principais motivos desses cancelamentos e quais as ações mais eficientes para reduzir esse número.\n",
    "\n",
    "Base de dados e arquivos: https://drive.google.com/drive/folders/1uDesZePdkhiraJmiyeZ-w5tfc8XsNYFZ?usp=drive_link"
   ]
  },
  {
   "cell_type": "code",
   "execution_count": 11,
   "metadata": {},
   "outputs": [
    {
     "name": "stdout",
     "output_type": "stream",
     "text": [
      "Unexpected exception formatting exception. Falling back to standard exception\n"
     ]
    },
    {
     "name": "stderr",
     "output_type": "stream",
     "text": [
      "Traceback (most recent call last):\n",
      "  File \"C:\\Users\\danie.DESKTOP-FTQHHEL.000\\AppData\\Roaming\\Python\\Python311\\site-packages\\IPython\\core\\interactiveshell.py\", line 3508, in run_code\n",
      "    exec(code_obj, self.user_global_ns, self.user_ns)\n",
      "  File \"C:\\Windows\\Temp\\ipykernel_16844\\2957645755.py\", line 5, in <module>\n",
      "    tabela = pd.read_csv(\"cancelamentos.csv\")\n",
      "             ^^^^^^^^^^^^^^^^^^^^^^^^^^^^^^^^\n",
      "  File \"c:\\Users\\danie.DESKTOP-FTQHHEL.000\\AppData\\Local\\Programs\\Python\\Python311\\Lib\\site-packages\\pandas\\io\\parsers\\readers.py\", line 912, in read_csv\n",
      "    return _read(filepath_or_buffer, kwds)\n",
      "           ^^^^^^^^^^^^^^^^^^^^^^^^^^^^^^^\n",
      "  File \"c:\\Users\\danie.DESKTOP-FTQHHEL.000\\AppData\\Local\\Programs\\Python\\Python311\\Lib\\site-packages\\pandas\\io\\parsers\\readers.py\", line 577, in _read\n",
      "    parser = TextFileReader(filepath_or_buffer, **kwds)\n",
      "             ^^^^^^^^^^^^^^^^^^^^^^^^^^^^^^^^^^^^^^^^^^\n",
      "  File \"c:\\Users\\danie.DESKTOP-FTQHHEL.000\\AppData\\Local\\Programs\\Python\\Python311\\Lib\\site-packages\\pandas\\io\\parsers\\readers.py\", line 1407, in __init__\n",
      "    self._engine = self._make_engine(f, self.engine)\n",
      "                   ^^^^^^^^^^^^^^^^^^^^^^^^^^^^^^^^^\n",
      "  File \"c:\\Users\\danie.DESKTOP-FTQHHEL.000\\AppData\\Local\\Programs\\Python\\Python311\\Lib\\site-packages\\pandas\\io\\parsers\\readers.py\", line 1661, in _make_engine\n",
      "    self.handles = get_handle(\n",
      "                   ^^^^^^^^^^^\n",
      "  File \"c:\\Users\\danie.DESKTOP-FTQHHEL.000\\AppData\\Local\\Programs\\Python\\Python311\\Lib\\site-packages\\pandas\\io\\common.py\", line 859, in get_handle\n",
      "    handle = open(\n",
      "             ^^^^^\n",
      "FileNotFoundError: [Errno 2] No such file or directory: 'cancelamentos.csv'\n",
      "\n",
      "During handling of the above exception, another exception occurred:\n",
      "\n",
      "Traceback (most recent call last):\n",
      "  File \"C:\\Users\\danie.DESKTOP-FTQHHEL.000\\AppData\\Roaming\\Python\\Python311\\site-packages\\IPython\\core\\interactiveshell.py\", line 2105, in showtraceback\n",
      "    stb = self.InteractiveTB.structured_traceback(\n",
      "          ^^^^^^^^^^^^^^^^^^^^^^^^^^^^^^^^^^^^^^^^\n",
      "  File \"C:\\Users\\danie.DESKTOP-FTQHHEL.000\\AppData\\Roaming\\Python\\Python311\\site-packages\\IPython\\core\\ultratb.py\", line 1428, in structured_traceback\n",
      "    return FormattedTB.structured_traceback(\n",
      "           ^^^^^^^^^^^^^^^^^^^^^^^^^^^^^^^^^\n",
      "  File \"C:\\Users\\danie.DESKTOP-FTQHHEL.000\\AppData\\Roaming\\Python\\Python311\\site-packages\\IPython\\core\\ultratb.py\", line 1319, in structured_traceback\n",
      "    return VerboseTB.structured_traceback(\n",
      "           ^^^^^^^^^^^^^^^^^^^^^^^^^^^^^^^\n",
      "  File \"C:\\Users\\danie.DESKTOP-FTQHHEL.000\\AppData\\Roaming\\Python\\Python311\\site-packages\\IPython\\core\\ultratb.py\", line 1172, in structured_traceback\n",
      "    formatted_exception = self.format_exception_as_a_whole(etype, evalue, etb, number_of_lines_of_context,\n",
      "                          ^^^^^^^^^^^^^^^^^^^^^^^^^^^^^^^^^^^^^^^^^^^^^^^^^^^^^^^^^^^^^^^^^^^^^^^^^^^^^^^^\n",
      "  File \"C:\\Users\\danie.DESKTOP-FTQHHEL.000\\AppData\\Roaming\\Python\\Python311\\site-packages\\IPython\\core\\ultratb.py\", line 1062, in format_exception_as_a_whole\n",
      "    self.get_records(etb, number_of_lines_of_context, tb_offset) if etb else []\n",
      "    ^^^^^^^^^^^^^^^^^^^^^^^^^^^^^^^^^^^^^^^^^^^^^^^^^^^^^^^^^^^^\n",
      "  File \"C:\\Users\\danie.DESKTOP-FTQHHEL.000\\AppData\\Roaming\\Python\\Python311\\site-packages\\IPython\\core\\ultratb.py\", line 1114, in get_records\n",
      "    style = stack_data.style_with_executing_node(style, self._tb_highlight)\n",
      "            ^^^^^^^^^^^^^^^^^^^^^^^^^^^^^^^^^^^^^^^^^^^^^^^^^^^^^^^^^^^^^^^\n",
      "  File \"C:\\Users\\danie.DESKTOP-FTQHHEL.000\\AppData\\Roaming\\Python\\Python311\\site-packages\\stack_data\\core.py\", line 455, in style_with_executing_node\n",
      "    class NewStyle(style):\n",
      "  File \"c:\\Users\\danie.DESKTOP-FTQHHEL.000\\AppData\\Local\\Programs\\Python\\Python311\\Lib\\site-packages\\pygments\\style.py\", line 91, in __new__\n",
      "    ndef[4] = colorformat(styledef[3:])\n",
      "              ^^^^^^^^^^^^^^^^^^^^^^^^^\n",
      "  File \"c:\\Users\\danie.DESKTOP-FTQHHEL.000\\AppData\\Local\\Programs\\Python\\Python311\\Lib\\site-packages\\pygments\\style.py\", line 58, in colorformat\n",
      "    assert False, \"wrong color format %r\" % text\n",
      "AssertionError: wrong color format 'ansiyellow'\n"
     ]
    }
   ],
   "source": [
    "# Passo a Passo do seu projeto\n",
    "# Passo 1: Importar a base de dados\n",
    "import pandas as pd\n",
    "\n",
    "tabela = pd.read_csv(\"cancelamentos.csv\")\n",
    "\n",
    "# Passo 2: Visualizar a base de dados\n",
    "#Informação que não te ajuda , te atrapalha\n",
    "#linha -> axis= 0\n",
    "#coluna -> axis = 1\n",
    "tabela = tabela.drop(\"CustomerID\", axis=1)\n",
    "display(tabela)\n",
    "\n"
   ]
  },
  {
   "cell_type": "code",
   "execution_count": 2,
   "metadata": {},
   "outputs": [
    {
     "name": "stdout",
     "output_type": "stream",
     "text": [
      "Unexpected exception formatting exception. Falling back to standard exception\n"
     ]
    },
    {
     "name": "stderr",
     "output_type": "stream",
     "text": [
      "Traceback (most recent call last):\n",
      "  File \"C:\\Users\\danie.DESKTOP-FTQHHEL.000\\AppData\\Roaming\\Python\\Python311\\site-packages\\IPython\\core\\interactiveshell.py\", line 3508, in run_code\n",
      "    exec(code_obj, self.user_global_ns, self.user_ns)\n",
      "  File \"C:\\Windows\\Temp\\ipykernel_16844\\416208430.py\", line 3, in <module>\n",
      "    tabela = tabela.dropna()\n",
      "             ^^^^^^\n",
      "NameError: name 'tabela' is not defined\n",
      "\n",
      "During handling of the above exception, another exception occurred:\n",
      "\n",
      "Traceback (most recent call last):\n",
      "  File \"C:\\Users\\danie.DESKTOP-FTQHHEL.000\\AppData\\Roaming\\Python\\Python311\\site-packages\\IPython\\core\\interactiveshell.py\", line 2105, in showtraceback\n",
      "    stb = self.InteractiveTB.structured_traceback(\n",
      "          ^^^^^^^^^^^^^^^^^^^^^^^^^^^^^^^^^^^^^^^^\n",
      "  File \"C:\\Users\\danie.DESKTOP-FTQHHEL.000\\AppData\\Roaming\\Python\\Python311\\site-packages\\IPython\\core\\ultratb.py\", line 1428, in structured_traceback\n",
      "    return FormattedTB.structured_traceback(\n",
      "           ^^^^^^^^^^^^^^^^^^^^^^^^^^^^^^^^^\n",
      "  File \"C:\\Users\\danie.DESKTOP-FTQHHEL.000\\AppData\\Roaming\\Python\\Python311\\site-packages\\IPython\\core\\ultratb.py\", line 1319, in structured_traceback\n",
      "    return VerboseTB.structured_traceback(\n",
      "           ^^^^^^^^^^^^^^^^^^^^^^^^^^^^^^^\n",
      "  File \"C:\\Users\\danie.DESKTOP-FTQHHEL.000\\AppData\\Roaming\\Python\\Python311\\site-packages\\IPython\\core\\ultratb.py\", line 1172, in structured_traceback\n",
      "    formatted_exception = self.format_exception_as_a_whole(etype, evalue, etb, number_of_lines_of_context,\n",
      "                          ^^^^^^^^^^^^^^^^^^^^^^^^^^^^^^^^^^^^^^^^^^^^^^^^^^^^^^^^^^^^^^^^^^^^^^^^^^^^^^^^\n",
      "  File \"C:\\Users\\danie.DESKTOP-FTQHHEL.000\\AppData\\Roaming\\Python\\Python311\\site-packages\\IPython\\core\\ultratb.py\", line 1062, in format_exception_as_a_whole\n",
      "    self.get_records(etb, number_of_lines_of_context, tb_offset) if etb else []\n",
      "    ^^^^^^^^^^^^^^^^^^^^^^^^^^^^^^^^^^^^^^^^^^^^^^^^^^^^^^^^^^^^\n",
      "  File \"C:\\Users\\danie.DESKTOP-FTQHHEL.000\\AppData\\Roaming\\Python\\Python311\\site-packages\\IPython\\core\\ultratb.py\", line 1114, in get_records\n",
      "    style = stack_data.style_with_executing_node(style, self._tb_highlight)\n",
      "            ^^^^^^^^^^^^^^^^^^^^^^^^^^^^^^^^^^^^^^^^^^^^^^^^^^^^^^^^^^^^^^^\n",
      "  File \"C:\\Users\\danie.DESKTOP-FTQHHEL.000\\AppData\\Roaming\\Python\\Python311\\site-packages\\stack_data\\core.py\", line 455, in style_with_executing_node\n",
      "    class NewStyle(style):\n",
      "  File \"c:\\Users\\danie.DESKTOP-FTQHHEL.000\\AppData\\Local\\Programs\\Python\\Python311\\Lib\\site-packages\\pygments\\style.py\", line 91, in __new__\n",
      "    ndef[4] = colorformat(styledef[3:])\n",
      "              ^^^^^^^^^^^^^^^^^^^^^^^^^\n",
      "  File \"c:\\Users\\danie.DESKTOP-FTQHHEL.000\\AppData\\Local\\Programs\\Python\\Python311\\Lib\\site-packages\\pygments\\style.py\", line 58, in colorformat\n",
      "    assert False, \"wrong color format %r\" % text\n",
      "AssertionError: wrong color format 'ansiyellow'\n"
     ]
    }
   ],
   "source": [
    "\n",
    "# Passo 3: Tratamento de erros (resolver as cagadas base de dados)\n",
    "# tratar valores vazios\n",
    "tabela = tabela.dropna()\n",
    "display(tabela.info())\n",
    "\n",
    "\n"
   ]
  },
  {
   "cell_type": "code",
   "execution_count": 3,
   "metadata": {},
   "outputs": [
    {
     "name": "stdout",
     "output_type": "stream",
     "text": [
      "Unexpected exception formatting exception. Falling back to standard exception\n"
     ]
    },
    {
     "name": "stderr",
     "output_type": "stream",
     "text": [
      "Traceback (most recent call last):\n",
      "  File \"C:\\Users\\danie.DESKTOP-FTQHHEL.000\\AppData\\Roaming\\Python\\Python311\\site-packages\\IPython\\core\\interactiveshell.py\", line 3508, in run_code\n",
      "    exec(code_obj, self.user_global_ns, self.user_ns)\n",
      "  File \"C:\\Windows\\Temp\\ipykernel_16844\\239132057.py\", line 2, in <module>\n",
      "    display(tabela[\"cancelou\"].value_counts())\n",
      "            ^^^^^^\n",
      "NameError: name 'tabela' is not defined\n",
      "\n",
      "During handling of the above exception, another exception occurred:\n",
      "\n",
      "Traceback (most recent call last):\n",
      "  File \"C:\\Users\\danie.DESKTOP-FTQHHEL.000\\AppData\\Roaming\\Python\\Python311\\site-packages\\IPython\\core\\interactiveshell.py\", line 2105, in showtraceback\n",
      "    stb = self.InteractiveTB.structured_traceback(\n",
      "          ^^^^^^^^^^^^^^^^^^^^^^^^^^^^^^^^^^^^^^^^\n",
      "  File \"C:\\Users\\danie.DESKTOP-FTQHHEL.000\\AppData\\Roaming\\Python\\Python311\\site-packages\\IPython\\core\\ultratb.py\", line 1428, in structured_traceback\n",
      "    return FormattedTB.structured_traceback(\n",
      "           ^^^^^^^^^^^^^^^^^^^^^^^^^^^^^^^^^\n",
      "  File \"C:\\Users\\danie.DESKTOP-FTQHHEL.000\\AppData\\Roaming\\Python\\Python311\\site-packages\\IPython\\core\\ultratb.py\", line 1319, in structured_traceback\n",
      "    return VerboseTB.structured_traceback(\n",
      "           ^^^^^^^^^^^^^^^^^^^^^^^^^^^^^^^\n",
      "  File \"C:\\Users\\danie.DESKTOP-FTQHHEL.000\\AppData\\Roaming\\Python\\Python311\\site-packages\\IPython\\core\\ultratb.py\", line 1172, in structured_traceback\n",
      "    formatted_exception = self.format_exception_as_a_whole(etype, evalue, etb, number_of_lines_of_context,\n",
      "                          ^^^^^^^^^^^^^^^^^^^^^^^^^^^^^^^^^^^^^^^^^^^^^^^^^^^^^^^^^^^^^^^^^^^^^^^^^^^^^^^^\n",
      "  File \"C:\\Users\\danie.DESKTOP-FTQHHEL.000\\AppData\\Roaming\\Python\\Python311\\site-packages\\IPython\\core\\ultratb.py\", line 1062, in format_exception_as_a_whole\n",
      "    self.get_records(etb, number_of_lines_of_context, tb_offset) if etb else []\n",
      "    ^^^^^^^^^^^^^^^^^^^^^^^^^^^^^^^^^^^^^^^^^^^^^^^^^^^^^^^^^^^^\n",
      "  File \"C:\\Users\\danie.DESKTOP-FTQHHEL.000\\AppData\\Roaming\\Python\\Python311\\site-packages\\IPython\\core\\ultratb.py\", line 1114, in get_records\n",
      "    style = stack_data.style_with_executing_node(style, self._tb_highlight)\n",
      "            ^^^^^^^^^^^^^^^^^^^^^^^^^^^^^^^^^^^^^^^^^^^^^^^^^^^^^^^^^^^^^^^\n",
      "  File \"C:\\Users\\danie.DESKTOP-FTQHHEL.000\\AppData\\Roaming\\Python\\Python311\\site-packages\\stack_data\\core.py\", line 455, in style_with_executing_node\n",
      "    class NewStyle(style):\n",
      "  File \"c:\\Users\\danie.DESKTOP-FTQHHEL.000\\AppData\\Local\\Programs\\Python\\Python311\\Lib\\site-packages\\pygments\\style.py\", line 91, in __new__\n",
      "    ndef[4] = colorformat(styledef[3:])\n",
      "              ^^^^^^^^^^^^^^^^^^^^^^^^^\n",
      "  File \"c:\\Users\\danie.DESKTOP-FTQHHEL.000\\AppData\\Local\\Programs\\Python\\Python311\\Lib\\site-packages\\pygments\\style.py\", line 58, in colorformat\n",
      "    assert False, \"wrong color format %r\" % text\n",
      "AssertionError: wrong color format 'ansiyellow'\n"
     ]
    }
   ],
   "source": [
    "# Passo 4: Análise inicial dos dados (entender como estão os cancelamentos)\n",
    "display(tabela[\"cancelou\"].value_counts())\n",
    "display(tabela[\"cancelou\"].value_counts(normalize=True).map(\"{:.1%}\".format))\n"
   ]
  },
  {
   "cell_type": "code",
   "execution_count": 4,
   "metadata": {},
   "outputs": [
    {
     "name": "stdout",
     "output_type": "stream",
     "text": [
      "Unexpected exception formatting exception. Falling back to standard exception\n"
     ]
    },
    {
     "name": "stderr",
     "output_type": "stream",
     "text": [
      "Traceback (most recent call last):\n",
      "  File \"C:\\Users\\danie.DESKTOP-FTQHHEL.000\\AppData\\Roaming\\Python\\Python311\\site-packages\\IPython\\core\\interactiveshell.py\", line 3508, in run_code\n",
      "    exec(code_obj, self.user_global_ns, self.user_ns)\n",
      "  File \"C:\\Windows\\Temp\\ipykernel_16844\\3198566671.py\", line 1, in <module>\n",
      "    display(tabela[\"cancelou\"].value_counts())\n",
      "            ^^^^^^\n",
      "NameError: name 'tabela' is not defined\n",
      "\n",
      "During handling of the above exception, another exception occurred:\n",
      "\n",
      "Traceback (most recent call last):\n",
      "  File \"C:\\Users\\danie.DESKTOP-FTQHHEL.000\\AppData\\Roaming\\Python\\Python311\\site-packages\\IPython\\core\\interactiveshell.py\", line 2105, in showtraceback\n",
      "    stb = self.InteractiveTB.structured_traceback(\n",
      "          ^^^^^^^^^^^^^^^^^^^^^^^^^^^^^^^^^^^^^^^^\n",
      "  File \"C:\\Users\\danie.DESKTOP-FTQHHEL.000\\AppData\\Roaming\\Python\\Python311\\site-packages\\IPython\\core\\ultratb.py\", line 1428, in structured_traceback\n",
      "    return FormattedTB.structured_traceback(\n",
      "           ^^^^^^^^^^^^^^^^^^^^^^^^^^^^^^^^^\n",
      "  File \"C:\\Users\\danie.DESKTOP-FTQHHEL.000\\AppData\\Roaming\\Python\\Python311\\site-packages\\IPython\\core\\ultratb.py\", line 1319, in structured_traceback\n",
      "    return VerboseTB.structured_traceback(\n",
      "           ^^^^^^^^^^^^^^^^^^^^^^^^^^^^^^^\n",
      "  File \"C:\\Users\\danie.DESKTOP-FTQHHEL.000\\AppData\\Roaming\\Python\\Python311\\site-packages\\IPython\\core\\ultratb.py\", line 1172, in structured_traceback\n",
      "    formatted_exception = self.format_exception_as_a_whole(etype, evalue, etb, number_of_lines_of_context,\n",
      "                          ^^^^^^^^^^^^^^^^^^^^^^^^^^^^^^^^^^^^^^^^^^^^^^^^^^^^^^^^^^^^^^^^^^^^^^^^^^^^^^^^\n",
      "  File \"C:\\Users\\danie.DESKTOP-FTQHHEL.000\\AppData\\Roaming\\Python\\Python311\\site-packages\\IPython\\core\\ultratb.py\", line 1062, in format_exception_as_a_whole\n",
      "    self.get_records(etb, number_of_lines_of_context, tb_offset) if etb else []\n",
      "    ^^^^^^^^^^^^^^^^^^^^^^^^^^^^^^^^^^^^^^^^^^^^^^^^^^^^^^^^^^^^\n",
      "  File \"C:\\Users\\danie.DESKTOP-FTQHHEL.000\\AppData\\Roaming\\Python\\Python311\\site-packages\\IPython\\core\\ultratb.py\", line 1114, in get_records\n",
      "    style = stack_data.style_with_executing_node(style, self._tb_highlight)\n",
      "            ^^^^^^^^^^^^^^^^^^^^^^^^^^^^^^^^^^^^^^^^^^^^^^^^^^^^^^^^^^^^^^^\n",
      "  File \"C:\\Users\\danie.DESKTOP-FTQHHEL.000\\AppData\\Roaming\\Python\\Python311\\site-packages\\stack_data\\core.py\", line 455, in style_with_executing_node\n",
      "    class NewStyle(style):\n",
      "  File \"c:\\Users\\danie.DESKTOP-FTQHHEL.000\\AppData\\Local\\Programs\\Python\\Python311\\Lib\\site-packages\\pygments\\style.py\", line 91, in __new__\n",
      "    ndef[4] = colorformat(styledef[3:])\n",
      "              ^^^^^^^^^^^^^^^^^^^^^^^^^\n",
      "  File \"c:\\Users\\danie.DESKTOP-FTQHHEL.000\\AppData\\Local\\Programs\\Python\\Python311\\Lib\\site-packages\\pygments\\style.py\", line 58, in colorformat\n",
      "    assert False, \"wrong color format %r\" % text\n",
      "AssertionError: wrong color format 'ansiyellow'\n"
     ]
    }
   ],
   "source": [
    "display(tabela[\"cancelou\"].value_counts())\n",
    "display(tabela[\"cancelou\"].value_counts(normalize=True).map(\"{:.1%}\".format))\n"
   ]
  },
  {
   "cell_type": "code",
   "execution_count": 5,
   "metadata": {},
   "outputs": [
    {
     "name": "stdout",
     "output_type": "stream",
     "text": [
      "Unexpected exception formatting exception. Falling back to standard exception\n"
     ]
    },
    {
     "name": "stderr",
     "output_type": "stream",
     "text": [
      "Traceback (most recent call last):\n",
      "  File \"C:\\Users\\danie.DESKTOP-FTQHHEL.000\\AppData\\Roaming\\Python\\Python311\\site-packages\\IPython\\core\\interactiveshell.py\", line 3508, in run_code\n",
      "    exec(code_obj, self.user_global_ns, self.user_ns)\n",
      "  File \"C:\\Windows\\Temp\\ipykernel_16844\\2199732312.py\", line 1, in <module>\n",
      "    display(tabela.groupby(\"duracao_contrato\").mean())\n",
      "            ^^^^^^\n",
      "NameError: name 'tabela' is not defined\n",
      "\n",
      "During handling of the above exception, another exception occurred:\n",
      "\n",
      "Traceback (most recent call last):\n",
      "  File \"C:\\Users\\danie.DESKTOP-FTQHHEL.000\\AppData\\Roaming\\Python\\Python311\\site-packages\\IPython\\core\\interactiveshell.py\", line 2105, in showtraceback\n",
      "    stb = self.InteractiveTB.structured_traceback(\n",
      "          ^^^^^^^^^^^^^^^^^^^^^^^^^^^^^^^^^^^^^^^^\n",
      "  File \"C:\\Users\\danie.DESKTOP-FTQHHEL.000\\AppData\\Roaming\\Python\\Python311\\site-packages\\IPython\\core\\ultratb.py\", line 1428, in structured_traceback\n",
      "    return FormattedTB.structured_traceback(\n",
      "           ^^^^^^^^^^^^^^^^^^^^^^^^^^^^^^^^^\n",
      "  File \"C:\\Users\\danie.DESKTOP-FTQHHEL.000\\AppData\\Roaming\\Python\\Python311\\site-packages\\IPython\\core\\ultratb.py\", line 1319, in structured_traceback\n",
      "    return VerboseTB.structured_traceback(\n",
      "           ^^^^^^^^^^^^^^^^^^^^^^^^^^^^^^^\n",
      "  File \"C:\\Users\\danie.DESKTOP-FTQHHEL.000\\AppData\\Roaming\\Python\\Python311\\site-packages\\IPython\\core\\ultratb.py\", line 1172, in structured_traceback\n",
      "    formatted_exception = self.format_exception_as_a_whole(etype, evalue, etb, number_of_lines_of_context,\n",
      "                          ^^^^^^^^^^^^^^^^^^^^^^^^^^^^^^^^^^^^^^^^^^^^^^^^^^^^^^^^^^^^^^^^^^^^^^^^^^^^^^^^\n",
      "  File \"C:\\Users\\danie.DESKTOP-FTQHHEL.000\\AppData\\Roaming\\Python\\Python311\\site-packages\\IPython\\core\\ultratb.py\", line 1062, in format_exception_as_a_whole\n",
      "    self.get_records(etb, number_of_lines_of_context, tb_offset) if etb else []\n",
      "    ^^^^^^^^^^^^^^^^^^^^^^^^^^^^^^^^^^^^^^^^^^^^^^^^^^^^^^^^^^^^\n",
      "  File \"C:\\Users\\danie.DESKTOP-FTQHHEL.000\\AppData\\Roaming\\Python\\Python311\\site-packages\\IPython\\core\\ultratb.py\", line 1114, in get_records\n",
      "    style = stack_data.style_with_executing_node(style, self._tb_highlight)\n",
      "            ^^^^^^^^^^^^^^^^^^^^^^^^^^^^^^^^^^^^^^^^^^^^^^^^^^^^^^^^^^^^^^^\n",
      "  File \"C:\\Users\\danie.DESKTOP-FTQHHEL.000\\AppData\\Roaming\\Python\\Python311\\site-packages\\stack_data\\core.py\", line 455, in style_with_executing_node\n",
      "    class NewStyle(style):\n",
      "  File \"c:\\Users\\danie.DESKTOP-FTQHHEL.000\\AppData\\Local\\Programs\\Python\\Python311\\Lib\\site-packages\\pygments\\style.py\", line 91, in __new__\n",
      "    ndef[4] = colorformat(styledef[3:])\n",
      "              ^^^^^^^^^^^^^^^^^^^^^^^^^\n",
      "  File \"c:\\Users\\danie.DESKTOP-FTQHHEL.000\\AppData\\Local\\Programs\\Python\\Python311\\Lib\\site-packages\\pygments\\style.py\", line 58, in colorformat\n",
      "    assert False, \"wrong color format %r\" % text\n",
      "AssertionError: wrong color format 'ansiyellow'\n"
     ]
    }
   ],
   "source": [
    "display(tabela.groupby(\"duracao_contrato\").mean())\n",
    "#display(tabela.groupby(\"assinatura\").mean())\n",
    "\n"
   ]
  },
  {
   "cell_type": "code",
   "execution_count": 6,
   "metadata": {},
   "outputs": [
    {
     "name": "stdout",
     "output_type": "stream",
     "text": [
      "Unexpected exception formatting exception. Falling back to standard exception\n"
     ]
    },
    {
     "name": "stderr",
     "output_type": "stream",
     "text": [
      "Traceback (most recent call last):\n",
      "  File \"C:\\Users\\danie.DESKTOP-FTQHHEL.000\\AppData\\Roaming\\Python\\Python311\\site-packages\\IPython\\core\\interactiveshell.py\", line 3508, in run_code\n",
      "    exec(code_obj, self.user_global_ns, self.user_ns)\n",
      "  File \"C:\\Windows\\Temp\\ipykernel_16844\\3968617328.py\", line 2, in <module>\n",
      "    tabela= tabela[tabela[\"duracao_contrato\"]!=\"Monthiy\"]\n",
      "            ^^^^^^\n",
      "NameError: name 'tabela' is not defined\n",
      "\n",
      "During handling of the above exception, another exception occurred:\n",
      "\n",
      "Traceback (most recent call last):\n",
      "  File \"C:\\Users\\danie.DESKTOP-FTQHHEL.000\\AppData\\Roaming\\Python\\Python311\\site-packages\\IPython\\core\\interactiveshell.py\", line 2105, in showtraceback\n",
      "    stb = self.InteractiveTB.structured_traceback(\n",
      "          ^^^^^^^^^^^^^^^^^^^^^^^^^^^^^^^^^^^^^^^^\n",
      "  File \"C:\\Users\\danie.DESKTOP-FTQHHEL.000\\AppData\\Roaming\\Python\\Python311\\site-packages\\IPython\\core\\ultratb.py\", line 1428, in structured_traceback\n",
      "    return FormattedTB.structured_traceback(\n",
      "           ^^^^^^^^^^^^^^^^^^^^^^^^^^^^^^^^^\n",
      "  File \"C:\\Users\\danie.DESKTOP-FTQHHEL.000\\AppData\\Roaming\\Python\\Python311\\site-packages\\IPython\\core\\ultratb.py\", line 1319, in structured_traceback\n",
      "    return VerboseTB.structured_traceback(\n",
      "           ^^^^^^^^^^^^^^^^^^^^^^^^^^^^^^^\n",
      "  File \"C:\\Users\\danie.DESKTOP-FTQHHEL.000\\AppData\\Roaming\\Python\\Python311\\site-packages\\IPython\\core\\ultratb.py\", line 1172, in structured_traceback\n",
      "    formatted_exception = self.format_exception_as_a_whole(etype, evalue, etb, number_of_lines_of_context,\n",
      "                          ^^^^^^^^^^^^^^^^^^^^^^^^^^^^^^^^^^^^^^^^^^^^^^^^^^^^^^^^^^^^^^^^^^^^^^^^^^^^^^^^\n",
      "  File \"C:\\Users\\danie.DESKTOP-FTQHHEL.000\\AppData\\Roaming\\Python\\Python311\\site-packages\\IPython\\core\\ultratb.py\", line 1062, in format_exception_as_a_whole\n",
      "    self.get_records(etb, number_of_lines_of_context, tb_offset) if etb else []\n",
      "    ^^^^^^^^^^^^^^^^^^^^^^^^^^^^^^^^^^^^^^^^^^^^^^^^^^^^^^^^^^^^\n",
      "  File \"C:\\Users\\danie.DESKTOP-FTQHHEL.000\\AppData\\Roaming\\Python\\Python311\\site-packages\\IPython\\core\\ultratb.py\", line 1114, in get_records\n",
      "    style = stack_data.style_with_executing_node(style, self._tb_highlight)\n",
      "            ^^^^^^^^^^^^^^^^^^^^^^^^^^^^^^^^^^^^^^^^^^^^^^^^^^^^^^^^^^^^^^^\n",
      "  File \"C:\\Users\\danie.DESKTOP-FTQHHEL.000\\AppData\\Roaming\\Python\\Python311\\site-packages\\stack_data\\core.py\", line 455, in style_with_executing_node\n",
      "    class NewStyle(style):\n",
      "  File \"c:\\Users\\danie.DESKTOP-FTQHHEL.000\\AppData\\Local\\Programs\\Python\\Python311\\Lib\\site-packages\\pygments\\style.py\", line 91, in __new__\n",
      "    ndef[4] = colorformat(styledef[3:])\n",
      "              ^^^^^^^^^^^^^^^^^^^^^^^^^\n",
      "  File \"c:\\Users\\danie.DESKTOP-FTQHHEL.000\\AppData\\Local\\Programs\\Python\\Python311\\Lib\\site-packages\\pygments\\style.py\", line 58, in colorformat\n",
      "    assert False, \"wrong color format %r\" % text\n",
      "AssertionError: wrong color format 'ansiyellow'\n"
     ]
    }
   ],
   "source": [
    "# contrato Mensal sempre cancela\n",
    "tabela= tabela[tabela[\"duracao_contrato\"]!=\"Monthiy\"]\n",
    "#vamos ver o cancelamento tirado os caras do mensal\n",
    "display(tabela[\"cancelou\"].value_counts())\n",
    "display(tabela[\"cancelou\"].value_counts(normalize=True).map(\"{:.1%}\".format))\n",
    "\n"
   ]
  },
  {
   "cell_type": "code",
   "execution_count": 7,
   "metadata": {},
   "outputs": [
    {
     "name": "stdout",
     "output_type": "stream",
     "text": [
      "Unexpected exception formatting exception. Falling back to standard exception\n"
     ]
    },
    {
     "name": "stderr",
     "output_type": "stream",
     "text": [
      "Traceback (most recent call last):\n",
      "  File \"C:\\Users\\danie.DESKTOP-FTQHHEL.000\\AppData\\Roaming\\Python\\Python311\\site-packages\\IPython\\core\\interactiveshell.py\", line 3508, in run_code\n",
      "    exec(code_obj, self.user_global_ns, self.user_ns)\n",
      "  File \"C:\\Windows\\Temp\\ipykernel_16844\\3990892312.py\", line 4, in <module>\n",
      "    for coluna in tabela.columns:\n",
      "                  ^^^^^^\n",
      "NameError: name 'tabela' is not defined\n",
      "\n",
      "During handling of the above exception, another exception occurred:\n",
      "\n",
      "Traceback (most recent call last):\n",
      "  File \"C:\\Users\\danie.DESKTOP-FTQHHEL.000\\AppData\\Roaming\\Python\\Python311\\site-packages\\IPython\\core\\interactiveshell.py\", line 2105, in showtraceback\n",
      "    stb = self.InteractiveTB.structured_traceback(\n",
      "          ^^^^^^^^^^^^^^^^^^^^^^^^^^^^^^^^^^^^^^^^\n",
      "  File \"C:\\Users\\danie.DESKTOP-FTQHHEL.000\\AppData\\Roaming\\Python\\Python311\\site-packages\\IPython\\core\\ultratb.py\", line 1428, in structured_traceback\n",
      "    return FormattedTB.structured_traceback(\n",
      "           ^^^^^^^^^^^^^^^^^^^^^^^^^^^^^^^^^\n",
      "  File \"C:\\Users\\danie.DESKTOP-FTQHHEL.000\\AppData\\Roaming\\Python\\Python311\\site-packages\\IPython\\core\\ultratb.py\", line 1319, in structured_traceback\n",
      "    return VerboseTB.structured_traceback(\n",
      "           ^^^^^^^^^^^^^^^^^^^^^^^^^^^^^^^\n",
      "  File \"C:\\Users\\danie.DESKTOP-FTQHHEL.000\\AppData\\Roaming\\Python\\Python311\\site-packages\\IPython\\core\\ultratb.py\", line 1172, in structured_traceback\n",
      "    formatted_exception = self.format_exception_as_a_whole(etype, evalue, etb, number_of_lines_of_context,\n",
      "                          ^^^^^^^^^^^^^^^^^^^^^^^^^^^^^^^^^^^^^^^^^^^^^^^^^^^^^^^^^^^^^^^^^^^^^^^^^^^^^^^^\n",
      "  File \"C:\\Users\\danie.DESKTOP-FTQHHEL.000\\AppData\\Roaming\\Python\\Python311\\site-packages\\IPython\\core\\ultratb.py\", line 1062, in format_exception_as_a_whole\n",
      "    self.get_records(etb, number_of_lines_of_context, tb_offset) if etb else []\n",
      "    ^^^^^^^^^^^^^^^^^^^^^^^^^^^^^^^^^^^^^^^^^^^^^^^^^^^^^^^^^^^^\n",
      "  File \"C:\\Users\\danie.DESKTOP-FTQHHEL.000\\AppData\\Roaming\\Python\\Python311\\site-packages\\IPython\\core\\ultratb.py\", line 1114, in get_records\n",
      "    style = stack_data.style_with_executing_node(style, self._tb_highlight)\n",
      "            ^^^^^^^^^^^^^^^^^^^^^^^^^^^^^^^^^^^^^^^^^^^^^^^^^^^^^^^^^^^^^^^\n",
      "  File \"C:\\Users\\danie.DESKTOP-FTQHHEL.000\\AppData\\Roaming\\Python\\Python311\\site-packages\\stack_data\\core.py\", line 455, in style_with_executing_node\n",
      "    class NewStyle(style):\n",
      "  File \"c:\\Users\\danie.DESKTOP-FTQHHEL.000\\AppData\\Local\\Programs\\Python\\Python311\\Lib\\site-packages\\pygments\\style.py\", line 91, in __new__\n",
      "    ndef[4] = colorformat(styledef[3:])\n",
      "              ^^^^^^^^^^^^^^^^^^^^^^^^^\n",
      "  File \"c:\\Users\\danie.DESKTOP-FTQHHEL.000\\AppData\\Local\\Programs\\Python\\Python311\\Lib\\site-packages\\pygments\\style.py\", line 58, in colorformat\n",
      "    assert False, \"wrong color format %r\" % text\n",
      "AssertionError: wrong color format 'ansiyellow'\n"
     ]
    }
   ],
   "source": [
    "# Passo 5: Analise profundanda da base de dado (encontrando a causa dos cancelamento)\n",
    "import plotly.express as px\n",
    "\n",
    "for coluna in tabela.columns:\n",
    "  grafico = px.histogram(tabela, x=coluna, color=\"cancelou\")\n",
    "  grafico.show()"
   ]
  },
  {
   "cell_type": "code",
   "execution_count": 8,
   "metadata": {},
   "outputs": [
    {
     "name": "stdout",
     "output_type": "stream",
     "text": [
      "Unexpected exception formatting exception. Falling back to standard exception\n"
     ]
    },
    {
     "name": "stderr",
     "output_type": "stream",
     "text": [
      "Traceback (most recent call last):\n",
      "  File \"C:\\Users\\danie.DESKTOP-FTQHHEL.000\\AppData\\Roaming\\Python\\Python311\\site-packages\\IPython\\core\\interactiveshell.py\", line 3508, in run_code\n",
      "    exec(code_obj, self.user_global_ns, self.user_ns)\n",
      "  File \"C:\\Windows\\Temp\\ipykernel_16844\\2503321042.py\", line 2, in <module>\n",
      "    tabela = tabela[tabela[\"ligacoes_callcenter\"]<5]\n",
      "             ^^^^^^\n",
      "NameError: name 'tabela' is not defined\n",
      "\n",
      "During handling of the above exception, another exception occurred:\n",
      "\n",
      "Traceback (most recent call last):\n",
      "  File \"C:\\Users\\danie.DESKTOP-FTQHHEL.000\\AppData\\Roaming\\Python\\Python311\\site-packages\\IPython\\core\\interactiveshell.py\", line 2105, in showtraceback\n",
      "    stb = self.InteractiveTB.structured_traceback(\n",
      "          ^^^^^^^^^^^^^^^^^^^^^^^^^^^^^^^^^^^^^^^^\n",
      "  File \"C:\\Users\\danie.DESKTOP-FTQHHEL.000\\AppData\\Roaming\\Python\\Python311\\site-packages\\IPython\\core\\ultratb.py\", line 1428, in structured_traceback\n",
      "    return FormattedTB.structured_traceback(\n",
      "           ^^^^^^^^^^^^^^^^^^^^^^^^^^^^^^^^^\n",
      "  File \"C:\\Users\\danie.DESKTOP-FTQHHEL.000\\AppData\\Roaming\\Python\\Python311\\site-packages\\IPython\\core\\ultratb.py\", line 1319, in structured_traceback\n",
      "    return VerboseTB.structured_traceback(\n",
      "           ^^^^^^^^^^^^^^^^^^^^^^^^^^^^^^^\n",
      "  File \"C:\\Users\\danie.DESKTOP-FTQHHEL.000\\AppData\\Roaming\\Python\\Python311\\site-packages\\IPython\\core\\ultratb.py\", line 1172, in structured_traceback\n",
      "    formatted_exception = self.format_exception_as_a_whole(etype, evalue, etb, number_of_lines_of_context,\n",
      "                          ^^^^^^^^^^^^^^^^^^^^^^^^^^^^^^^^^^^^^^^^^^^^^^^^^^^^^^^^^^^^^^^^^^^^^^^^^^^^^^^^\n",
      "  File \"C:\\Users\\danie.DESKTOP-FTQHHEL.000\\AppData\\Roaming\\Python\\Python311\\site-packages\\IPython\\core\\ultratb.py\", line 1062, in format_exception_as_a_whole\n",
      "    self.get_records(etb, number_of_lines_of_context, tb_offset) if etb else []\n",
      "    ^^^^^^^^^^^^^^^^^^^^^^^^^^^^^^^^^^^^^^^^^^^^^^^^^^^^^^^^^^^^\n",
      "  File \"C:\\Users\\danie.DESKTOP-FTQHHEL.000\\AppData\\Roaming\\Python\\Python311\\site-packages\\IPython\\core\\ultratb.py\", line 1114, in get_records\n",
      "    style = stack_data.style_with_executing_node(style, self._tb_highlight)\n",
      "            ^^^^^^^^^^^^^^^^^^^^^^^^^^^^^^^^^^^^^^^^^^^^^^^^^^^^^^^^^^^^^^^\n",
      "  File \"C:\\Users\\danie.DESKTOP-FTQHHEL.000\\AppData\\Roaming\\Python\\Python311\\site-packages\\stack_data\\core.py\", line 455, in style_with_executing_node\n",
      "    class NewStyle(style):\n",
      "  File \"c:\\Users\\danie.DESKTOP-FTQHHEL.000\\AppData\\Local\\Programs\\Python\\Python311\\Lib\\site-packages\\pygments\\style.py\", line 91, in __new__\n",
      "    ndef[4] = colorformat(styledef[3:])\n",
      "              ^^^^^^^^^^^^^^^^^^^^^^^^^\n",
      "  File \"c:\\Users\\danie.DESKTOP-FTQHHEL.000\\AppData\\Local\\Programs\\Python\\Python311\\Lib\\site-packages\\pygments\\style.py\", line 58, in colorformat\n",
      "    assert False, \"wrong color format %r\" % text\n",
      "AssertionError: wrong color format 'ansiyellow'\n"
     ]
    }
   ],
   "source": [
    "#ligacoes call center a parti de 5, canelem\n",
    "tabela = tabela[tabela[\"ligacoes_callcenter\"]<5]\n",
    "\n",
    "#dias de atraso, apartir de 21, cancelem\n",
    "tabela = tabela[tabela[\"dias_atraso\"]<=20]\n",
    "\n",
    "#vamos ver o cancelamento tirado os caras do mensal\n",
    "display(tabela[\"cancelou\"].value_counts())\n",
    "display(tabela[\"cancelou\"].value_counts(normalize=True).map(\"{:.1%}\".format))"
   ]
  }
 ],
 "metadata": {
  "kernelspec": {
   "display_name": "Python 3 (ipykernel)",
   "language": "python",
   "name": "python3"
  },
  "language_info": {
   "codemirror_mode": {
    "name": "ipython",
    "version": 3
   },
   "file_extension": ".py",
   "mimetype": "text/x-python",
   "name": "python",
   "nbconvert_exporter": "python",
   "pygments_lexer": "ipython3",
   "version": "3.11.4"
  }
 },
 "nbformat": 4,
 "nbformat_minor": 2
}
